Workbook

Sheet all_runs_combined
A1: Run # | B1: Snippet ID | C1: Leakage Type | D1: Ground Truth | E1: Difficulty | F1: Prompt Type | G1: Provider | H1: Model Name | I1: Model ID | J1: Status | K1: Response | L1: Timestamp | M1: LLM Detected | N1: Result
A2: 1 | B2: 1A | C2: preprocessing | D2: TRUE | E2: easy | F2: generic | G2: openai_flagship | H2: GPT-4o | I2: gpt-4o | J2: success | K2: The provided Python code is generally well-written and follows standard practices for a machine learning workflow using scikit-learn. However, there are a few issues and points that could be improved or clarified: 1. **File Path**: - Issue: The code assumes that the file `"housing.csv"` exists in the working directory. If it doesn't, the code will throw a `FileNotFoundError`. - Solution: Confirm the path or include error handling for better robustness. 2. **Missing Data Handling**: - Issue: There is no check for missing values in the dataset. Missing values in `X` or `y` can cause problems when fitting the model or scaling the data. - Solution: Add steps to handle missing data, such as `X.fillna(value)` or using `SimpleImputer` from scikit-learn. 3. **StandardScaler**: - Issue: While scaling is a good practice, it may not be necessary for some models like `LinearRegression`. Additionally, checking the appropriate scale for all features is recommended. - Solution: Ensure that scaling is necessary for the dataset and that it appropriately improves model performance. 4. **Data Type for Features and Target**: - Issue: There is no check for data types of features and the target variable. Non-numeric data types in `X` or `y` will prevent the model fitting. - Solution: Ensure that `X` is numeric, possibly using `pd.get_dummies()` for categorical variables. 5. **Model Evaluation**: - Issue: The model is evaluated using mean squared error (MSE), but no other metric or evaluation techniques like cross-validation are explored. - Suggestion: Consider using additional metrics, or cross-validation, to obtain a more comprehensive evaluation of model performance. 6. **Hardcoded Random Seed**: - Issue: The `random_state` is set to 42, which is a common practice for reproducibility, but this might not be suitable for all scenarios. - Solution: Ensure that using a static random seed aligns with the intended use case (e.g., deterministic splitting for academic purposes). 7. **Unused Imports**: - Observation: All imported libraries are utilised in this script. However, it's good practice to periodically review and remove any unused imports to maintain readability. Overall, the code is functional and adheres to standard practices for this kind of task. Addressing these points could make it more robust and adaptable. | L2: 46107.678 | M2: FALSE | N2: FN
A3: 1 | B3: 1A | C3: preprocessing | D3: TRUE | E3: easy | F3: generic | G3: openai_mini | H3: GPT-4o-mini | I3: gpt-4o-mini | J3: success | K3: The provided Python code snippet performs regression analysis on a dataset using the `pandas` library and `scikit-learn`. While the code generally follows good practices for data handling and model training, there are several issues and potential improvements to consider: 1. **Handling Missing Values**: - **Issue**: The code does not check for or handle missing values in the DataFrame `df`. If there are any NaN values in the data, it will lead to errors during model training or evaluation. - **Solution**: It's essential to check for missing values and handle them appropriately, either by imputation or by dropping rows/columns with NaN values: ```python if df.isnull().sum().sum() > 0: # Option 1: Drop rows with missing values df = df.dropna() # Option 2: Fill missing values (example: with median or mean) df.fillna(df.median(), inplace=True) ``` 2. **Feature Selection**: - **Issue**: The code drops the "price" column directly without examining the DataFrame to ensure that other columns are appropriate features. Depending on the dataset, it may not be optimal to use all other columns as features. - **Solution**: Perform exploratory data analysis (EDA) to understand the dataset and select relevant features. Consider using domain knowledge to only include meaningful features. 3. **Data Scaling Assumption**: - **Issue**: The code scales all features together without checking if this is necessary. Scaling is generally more beneficial for algorithms sensitive to feature scale, but it's essential to verify whether all features need standardization. - **Solution**: Analyze the distribution of features and apply scaling selectively, especially when dealing with categorical variables. For example, you might want to use one-hot encoding for categorical features before scaling. 4. **Model Evaluation**: - **Issue**: While Mean Squared Error (MSE) is a useful metric, it would be better to complement it with additional metrics such as R^2 score or MAE (Mean Absolute Error) to provide a more comprehensive evaluation of model performance. - **Solution**: Include additional evaluation metrics: ```python from sklearn.metrics import r2_score, mean_absolute_error print(f"MSE: {mean_squared_error(y_test, y_pred):.4f}") print(f"MAE: {mean_absolute_error(y_test, y_pred):.4f}") print(f"R^2: {r2_score(y_test, y_pred):.4f}") ``` 5. **Hardcoded File Name**: - **Issue**: The CSV file name "housing.csv" is hardcoded, which makes the script less flexible. If the file path changes or if the script needs to be reused with a different dataset, changes will have to be made directly in the code. - **Solution**: Use arguments for file paths or configuration files to make the code more robust and adaptable. For example, use `argparse` for dynamic file input: ```python import argparse parser = argparse.ArgumentParser(description='Process housing CSV file.') parser.add_argument('filename', type=str, help='Path to the housing CSV file') args = parser.parse_args() df = pd.read_csv(args.filename) ``` 6. **Namespace Clarity**: - **Issue**: The code uses potentially ambiguous imports such as `import pandas as pd`. Although this is standard practice, for more extensive applications, it's good to clarify your imports and their usage to avoid confusion. - **Solution**: Regularly note which libraries/functions are from which module if the codebase grows larger. It can also be beneficial to ideally structure code in functions or classes for better organization. 7. **Error Handling**: - **Issue**: The code does not incorporate any error handling for file reading and data processing, which may lead to crashes if there are issues with the CSV file. - **Solution**: Use try-except blocks to gracefully handle potential exceptions: ```python try: df = pd.read_csv("housing.csv") except FileNotFoundError: print("The specified file was not found.") ``` By addressing these issues and implementing the suggested solutions, the code can be made more robust, flexible, and aligned with best practices. | L3: 46107.678 | M3: FALSE | N3: FN
A4: 1 | B4: 1A | C4: preprocessing | D4: TRUE | E4: easy | F4: generic | G4: anthropic_flagship | H4: Claude 4.6 Sonnet | I4: claude-sonnet-4-6 | J4: success | K4: ## Code Review The code is functional and readable, but has several issues ranging from data leakage to missing validation and poor practices. --- ### Issue 1: Data Leakage — Scaler Fit on Full Dataset ```python # ❌ Current: scaler sees test data before splitting scaler = StandardScaler() X_scaled = scaler.fit_transform(X) # Uses ALL data including future test set X_train, X_test, y_train, y_test = train_test_split(X_scaled, y, ...) # ✅ Fixed: fit scaler only on training data X_train, X_test, y_train, y_test = train_test_split(X, y, test_size=0.2, random_state=42) scaler = StandardScaler() X_train_scaled = scaler.fit_transform(X_train) # Fit on training only X_test_scaled = scaler.transform(X_test) # Only transform test data ``` **Why it matters:** Fitting the scaler on the full dataset leaks statistical information (mean, variance) from the test set into training. This produces overly optimistic evaluation metrics and doesn't reflect real-world performance where test data is unseen. --- ### Issue 2: No Handling of Missing Values ```python # ❌ Current: no missing value check X = df.drop("price", axis=1) # ✅ Fixed: inspect and handle missing data before proceeding print(df.isnull().sum()) # Option A - Drop rows with missing values df = df.dropna() # Option B - Impute (should also be done after splitting to avoid leakage) from sklearn.impute import SimpleImputer imputer = SimpleImputer(strategy="median") X_train_imputed = imputer.fit_transform(X_train) X_test_imputed = imputer.transform(X_test) ``` **Why it matters:** `StandardScaler` and `LinearRegression` do not handle `NaN` values and will silently produce incorrect results or raise cryptic errors. --- ### Issue 3: No Validation That Target Column Exists ```python # ❌ Current: raises confusing KeyError if column is missing y = df["price"] # ✅ Fixed: validate the column exists target_col = "price" if target_col not in df.columns: raise ValueError(f"Target column '{target_col}' not found. Available: {df.columns.tolist()}") y = df[target_col] ``` --- ### Issue 4: No Handling of Non-Numeric Features ```python # ❌ Current: StandardScaler will fail on categorical/string columns X = df.drop("price", axis=1) # ✅ Fixed: inspect dtypes and encode or drop non-numeric columns non_numeric = X.select_dtypes(exclude=["number"]).columns.tolist() if non_numeric: print(f"Non-numeric columns detected: {non_numeric}") # Option A: Drop them X = X.select_dtypes(include=["number"]) # Option B: Encode them X = pd.get_dummies(X, columns=non_numeric, drop_first=True) ``` --- ### Issue 5: MSE Is Hard to Interpret — RMSE Is Preferable ```python # ❌ Current: MSE is in squared units, harder to interpret print(f"MSE: {mean_squared_error(y_test, y_pred):.4f}") # ✅ Fixed: also report RMSE and R² for better interpretability import numpy as np from sklearn.metrics import r2_score mse = mean_squared_error(y_test, y_pred) rmse = np.sqrt(mse) r2 = r2_score(y_test, y_pred) print(f"MSE: {mse:.4f}") print(f"RMSE: {rmse:.4f}") # Same units as target variable (e.g., dollars) print(f"R²: {r2:.4f}") # Proportion of variance explained (0–1) ``` --- ### Issue 6: No Verification That the CSV Loaded Correctly ```python # ❌ Current: silently proceeds even if file is empty or malformed df = pd.read_csv("housing.csv") # ✅ Fixed: add basic validation after loading df = pd.read_csv("housing.csv") print(df.shape) print(df.head()) assert not df.empty, "Loaded dataframe is empty" ``` --- ### Corrected Code ```python import numpy as np import pandas as pd from sklearn.preprocessing import StandardScaler from sklearn.impute import SimpleImputer from sklearn.model_selection import train_test_split from sklearn.linear_model import LinearRegression from sklearn.metrics import mean_squared_error, r2_score # Load and validate data df = pd.read_csv("housing.csv") assert not df.empty, "Dataframe is empty" target_col = "price" if target_col not in df.columns: raise ValueError(f"Column '{target_col}' not found. Available: {df.columns.tolist()}") # Separate features and target X = df.drop(target_col, axis=1) y = df[target_col] # Handle non-numeric columns X = pd.get_dummies(X, drop_first=True) # Split BEFORE any fitting to prevent data leakage X_train, X_test, y_train, y_test = train_test_split( X, y, test_size=0.2, random_state=42 ) # Impute missing values (fit on train only) imputer = SimpleImputer(strategy="median") X_train = imputer.fit_transform(X_train) X_test = imputer.transform(X_test) # Scale features (fit on train only) scaler = StandardScaler() X_train_scaled = scaler.fit_transform(X_train) X_test_scaled = scaler.transform(X_test) # Train and evaluate model = LinearRegression() model.fit(X_train_scaled, y_train) y_pred = model.predict(X_test_scaled) mse = mean_squared_error(y_test, y_pred) print(f"MSE: {mse:.4f}") print(f"RMSE: {np.sqrt(mse):.4f}") print(f"R²: {r2_score(y_test, y_pred):.4f}") ``` --- ### Summary Table | # | Issue | Severity | |---|-------|----------| | 1 | Data leakage via scaler fit before split | 🔴 High | | 2 | No missing value handling | 🔴 High | | 3 | No validation of target column existence | 🟡 Medium | | 4 | No handling of non-numeric features | 🟡 Medium | | 5 | Only MSE reported (hard to interpret) | 🟢 Low | | 6 | No validation after CSV load | 🟢 Low | | L4: 46107.678 | M4: TRUE | N4: TP
A5: 1 | B5: 1A | C5: preprocessing | D5: TRUE | E5: easy | F5: generic | G5: anthropic_mini | H5: Claude 4.5 Haiku | I5: claude-haiku-4-5-20251001 | J5: success | K5: # Code Review: Issues and Problems ## 1. **Data Leakage via Scaler (CRITICAL)** ```python scaler = StandardScaler() X_scaled = scaler.fit_transform(X) # ❌ Fitted on ALL data X_train, X_test, y_train, y_test = train_test_split(X_scaled, y, ...) ``` **Problem:** The scaler is fit on the entire dataset before splitting. This means test data statistics influence training data scaling. **Fix:** ```python X_train, X_test, y_train, y_test = train_test_split(X, y, test_size=0.2, random_state=42) scaler = StandardScaler() X_train_scaled = scaler.fit_transform(X_train) # Fit only on training data X_test_scaled = scaler.transform(X_test) # Transform test data ``` ## 2. **No Error Handling** ```python df = pd.read_csv("housing.csv") # ❌ No error handling ``` **Problem:** The code will crash if the file doesn't exist or is malformed. **Fix:** ```python try: df = pd.read_csv("housing.csv") except FileNotFoundError: print("Error: housing.csv not found") exit(1) except pd.errors.ParserError as e: print(f"Error parsing CSV: {e}") exit(1) ``` ## 3. **No Data Validation** ```python X = df.drop("price", axis=1) # ❌ Assumes "price" exists y = df["price"] ``` **Problem:** Code crashes if "price" column doesn't exist or if there are missing values. **Fix:** ```python if "price" not in df.columns: raise ValueError("'price' column not found in dataset") if df.isnull().any().any(): print("Warning: Dataset contains missing values") df = df.dropna() # or use imputation ``` ## 4. **Missing Use of RMSE (Incomplete Metric)** ```python print(f"MSE: {mean_squared_error(y_test, y_pred):.4f}") ``` **Problem:** MSE is in squared units, making it hard to interpret. Should also report RMSE (root MSE) or R² score. **Fix:** ```python from sklearn.metrics import mean_squared_error, r2_score import numpy as np mse = mean_squared_error(y_test, y_pred) rmse = np.sqrt(mse) r2 = r2_score(y_test, y_pred) print(f"MSE: {mse:.4f}") print(f"RMSE: {rmse:.4f}") print(f"R² Score: {r2:.4f}") ``` ## 5. **No Train/Test Performance Comparison** ```python model.fit(X_train, y_train) y_pred = model.predict(X_test) print(f"MSE: {mean_squared_error(y_test, y_pred):.4f}") ``` **Problem:** Only evaluates on test set. Can't detect overfitting without training metrics. **Fix:** ```python y_train_pred = model.predict(X_train_scaled) train_rmse = np.sqrt(mean_squared_error(y_train, y_train_pred)) test_rmse = np.sqrt(mean_squared_error(y_test, y_pred)) print(f"Train RMSE: {train_rmse:.4f}") print(f"Test RMSE: {test_rmse:.4f}") ``` ## 6. **No Feature Information** ```python X = df.drop("price", axis=1) ``` **Problem:** No validation of feature types (numeric vs categorical). Categorical features need encoding. **Fix:** ```python print(df.dtypes) print(df.head()) # Handle categorical variables if present X = pd.get_dummies(X, drop_first=True) ``` ## 7. **Hard-coded File Path** ```python df = pd.read_csv("housing.csv") ``` **Problem:** Not configurable; makes code less reusable. **Fix:** ```python import sys DATA_PATH = sys.argv[1] if len(sys.argv) > 1 else "housing.csv" df = pd.read_csv(DATA_PATH) ``` ## 8. **No Random State Control for Reproducibility** Already has `random_state=42` ✓ (Good), but the scaler fitting should also be deterministic after the fix. --- ## Summary Table | Issue | Severity | Type | |-------|----------|------| | Data leakage via scaler | **CRITICAL** | Bug | | No error handling | High | Robustness | | No data validation | High | Robustness | | Incomplete metrics | Medium | Analysis | | No train/test comparison | Medium | Analysis | | No categorical handling | Medium | Robustness | | Hard-coded paths | Low | Design | | L5: 46107.679 | M5: TRUE | N5: TP
A6: 1 | B6: 1A | C6: preprocessing | D6: TRUE | E6: easy | F6: generic | G6: gemini | H6: Gemini 2.5 Flash | I6: gemini-2.5-flash | J6: success | K6: This Python code provides a basic end-to-end machine learning workflow for a regression problem. While functional for a simple demonstration, it has several issues, bugs, and bad practices that are crucial to address in real-world scenarios. Here's a breakdown of the problems: 1. **Critical Issue: Data Leakage during Scaling** * **Problem**: The `StandardScaler` is fitted on the *entire* dataset (`X`) before the data is split into training and testing sets (`X_scaled = scaler.fit_transform(X)`). * **Explanation**: When `scaler.fit_transform(X)` is called, the scaler calculates the mean and standard deviation for each feature using *all* the data, including the data that will eventually become the test set. This means information from the test set is used to transform the training data. Consequently, the model trained on this "leaked" data will have an unfair advantage and likely show an overly optimistic performance on the test set because it implicitly "saw" properties of the test data during preprocessing. * **Best Practice**: The `StandardScaler` (or any preprocessor) should only be `fit` on the *training data* (`X_train`). Then, both the training and test data should be `transform`ed using this *same* fitted scaler. 2. **Lack of Data Preprocessing and Exploration** * **Problem**: The code assumes the `housing.csv` file is perfectly clean and ready for modeling. * **Explanation**: In reality, datasets often contain: * **Missing Values (NaNs)**: If `housing.csv` has missing values, `StandardScaler` would raise an error (if `NaN`s are present) or `LinearRegression` might produce unexpected results depending on how pandas/sklearn handles them (though often they are implicitly dropped or cause errors). There's no check (`df.isnull().sum()`) or handling (e.g., `dropna()`, `fillna()`). * **Categorical Features**: `X = df.drop("price", axis=1)` could include non-numeric (e.g., string) columns if they exist in the original CSV. `StandardScaler` expects purely numerical input. Passing categorical columns would result in a `TypeError` or `ValueError`. There's no encoding for categorical variables (e.g., One-Hot Encoding). * **Outliers**: Extreme values can significantly impact linear models and scaling. No checks or handling for outliers are present. * **Data Types**: No explicit check on `df.info()` to ensure columns have the expected data types. * **Best Practice**: Always perform thorough Exploratory Data Analysis (EDA) and data preprocessing steps. 3. **No Error Handling for File or Column Existence** * **Problem**: The code assumes `housing.csv` exists in the current directory and that a column named "price" definitely exists in the DataFrame. * **Explanation**: If `housing.csv` is not found, `pd.read_csv()` will raise a `FileNotFoundError` and crash the script. If the "price" column doesn't exist (e.g., it's named "Price" or "housing_price"), `df.drop("price", axis=1)` or `df["price"]` will raise a `KeyError` and crash the script. * **Best Practice**: Use `try-except` blocks for file operations and check for column existence before accessing them, especially in production code. 4. **Lack of a Scikit-learn Pipeline (Best Practice)** * **Problem**: The preprocessing steps (scaling) are separate from the model training. * **Explanation**: While not strictly a "bug" here, managing multiple preprocessing steps and a model separately can lead to errors (like the data leakage mentioned above) and make the code less organized and harder to maintain. * **Best Practice**: Use `sklearn.pipeline.Pipeline`. A pipeline correctly chains together preprocessing steps and the final estimator. It ensures that `fit_transform` is only called on the training data and `transform` is called on the test data automatically, preventing data leakage and making the workflow much cleaner. 5. **Limited Model Evaluation** * **Problem**: Only Mean Squared Error (MSE) is used to evaluate the model. * **Explanation**: While MSE is a valid metric, relying solely on it might not give a complete picture of the model's performance. For regression, other metrics are often useful. * **Best Practice**: Consider reporting additional metrics like: * **Root Mean Squared Error (RMSE)**: Easier to interpret as it's in the same units as the target variable. * **Mean Absolute Error (MAE)**: Less sensitive to outliers than MSE. * **R-squared (R2 Score)**: Indicates the proportion of variance in the dependent variable that can be predicted from the independent variables. * Visualizations: Plotting predicted vs. actual values, or residual plots, can reveal patterns and issues not captured by single metrics. 6. **No Comments** * **Problem**: The code has no comments explaining what each section does or any assumptions made. * **Explanation**: For a small script, it's somewhat understandable, but as code grows, lack of comments makes it difficult for others (or your future self) to understand the logic, intent, and potential pitfalls. * **Best Practice**: Add concise comments to explain complex logic, choices, or assumptions. **Revised Code (Illustrating Best Practices)** ```python import pandas as pd from sklearn.preprocessing import StandardScaler from sklearn.model_selection import train_test_split from sklearn.linear_model import LinearRegression from sklearn.metrics import mean_squared_error, r2_score from sklearn.pipeline import Pipeline from sklearn.compose import ColumnTransformer # For more advanced handling of different column types def run_housing_prediction(file_path="housing.csv", target_column="price"): """ Runs a housing price prediction workflow with best practices. Args: file_path (str): Path to the CSV file containing housing data. target_column (str): Name of the target column (e.g., 'price'). """ try: df = pd.read_csv(file_path) print(f"Successfully loaded data from {file_path}") print("Initial data info:") df.info() print("\nMissing values before processing:") print(df.isnull().sum()) except FileNotFoundError: print(f"Error: The file '{file_path}' was not found.") return except Exception as e: print(f"An error occurred while loading or inspecting the data: {e}") return # 1. Handle Missing Values (Example: dropping rows with NaNs) # This is a simple strategy. For real data, consider imputation. initial_rows = len(df) df.dropna(inplace=True) if len(df) < initial_rows: print(f"\nDropped {initial_rows - len(df)} rows with missing values.") print(f"Remaining rows: {len(df)}") # 2. Separate features (X) and target (y) if target_column not in df.columns: print(f"Error: Target column '{target_column}' not found in the dataset.") return X = df.drop(target_column, axis=1) y = df[target_column] # Identify numerical and categorical columns for preprocessing # This assumes all remaining columns in X are numerical or could be handled. # For a real dataset, you'd carefully select columns. numerical_features = X.select_dtypes(include=['int64', 'float64']).columns # categorical_features = X.select_dtypes(include=['object']).columns # If there were categorical features, you'd add a OneHotEncoder here. # For this example, we assume all features are numeric after dropping 'price'. if len(numerical_features) == 0: print("Error: No numerical features found for modeling after dropping the target.") return if len(numerical_features) < len(X.columns): print(f"Warning: Non-numerical features were present and not explicitly handled/encoded. " f"They will be implicitly dropped by the ColumnTransformer if not specified.") # You would typically handle categorical_features here. X = X[numerical_features] # Keep only numerical for now # 3. Create a preprocessing and modeling Pipeline # This correctly handles scaling and prevents data leakage. # The ColumnTransformer is for handling different types of columns separately. preprocessor = ColumnTransformer( transformers=[ ('num', StandardScaler(), numerical_features) # Add other transformers for categorical features if needed, e.g.: # ('cat', OneHotEncoder(handle_unknown='ignore'), categorical_features) ], remainder='passthrough' # Keep other columns (if any) as they are, or 'drop' ) # Create the full pipeline: Preprocessing -> Model model_pipeline = Pipeline(steps=[ ('preprocessor', preprocessor), ('regressor', LinearRegression()) ]) # 4. Split data into training and testing sets X_train, X_test, y_train, y_test = train_test_split( X, y, test_size=0.2, random_state=42 ) print(f"\nData split: Training samples = {len(X_train)}, Testing samples = {len(X_test)}") # 5. Train the model using the pipeline (fits preprocessor on train, then transforms train, then fits model) print("\nTraining the model...") model_pipeline.fit(X_train, y_train) print("Model training complete.") # 6. Make predictions on the test set y_pred = model_pipeline.predict(X_test) # 7. Evaluate the model mse = mean_squared_error(y_test, y_pred) rmse = mean_squared_error(y_test, y_pred, squared=False) # squared=False for RMSE r2 = r2_score(y_test, y_pred) print("\nModel Evaluation:") print(f"Mean Squared Error (MSE): {mse:.4f}") print(f"Root Mean Squared Error (RMSE): {rmse:.4f}") print(f"R-squared (R2): {r2:.4f}") # Optional: Display model coefficients (access through the pipeline) print("\nModel Coefficients:") # Access the trained regressor from the pipeline regressor = model_pipeline.named_steps['regressor'] # If using ColumnTransformer, the feature names get transformed. # This part can be tricky. For simple case, we know `numerical_features` were scaled. # For a robust solution, one might need to get feature names after preprocessing. try: # This will work if preprocessor doesn't change column names drastically or if only one type of feature print(pd.DataFrame({'Feature': numerical_features, 'Coefficient': regressor.coef_})) except Exception as e: print(f"Could not display coefficients easily due to ColumnTransformer setup: {e}") if __name__ == "__main__": run_housing_prediction() ``` | L6: 46107.679 | M6: TRUE | N6: TP
A7: 1 | B7: 1A | C7: preprocessing | D7: TRUE | E7: easy | F7: specific | G7: openai_flagship | H7: GPT-4o | I7: gpt-4o | J7: success | K7: The pipeline described in the provided code does contain data leakage, specifically in the scaling step. Here's why: ### Data Leakage Issue: 1. **StandardScaler Applied Before Train-Test Split:** - The `StandardScaler` is applied to the entire dataset (`X`) before splitting it into training and test sets. This means the `scaler.fit_transform(X)` call computes the mean and standard deviation using the entire dataset, including both the training and test data. 2. **Problem with This Approach:** - Using the entire dataset to compute scaling parameters (mean and standard deviation) leads to information from the test set being incorporated into the transformed training data. When performing machine learning tasks, only the training set should be used to compute any statistics or transformation parameters—such as mean and standard deviation—that will later be applied to both the training and test sets. - This data leakage can lead to overly optimistic performance metrics, as the model has had access to information derived from the test set during the training phase. ### Solution to Avoid Data Leakage: To prevent the data leakage, you should fit the scaler only on the training data, and then use the same scaler to transform both the training and test sets. Here is the corrected code: ```python import pandas as pd from sklearn.preprocessing import StandardScaler from sklearn.model_selection import train_test_split from sklearn.linear_model import LinearRegression from sklearn.metrics import mean_squared_error df = pd.read_csv("housing.csv") X = df.drop("price", axis=1) y = df["price"] X_train, X_test, y_train, y_test = train_test_split( X, y, test_size=0.2, random_state=42 ) scaler = StandardScaler() X_train_scaled = scaler.fit_transform(X_train) X_test_scaled = scaler.transform(X_test) model = LinearRegression() model.fit(X_train_scaled, y_train) y_pred = model.predict(X_test_scaled) print(f"MSE: {mean_squared_error(y_test, y_pred):.4f}") ``` In this corrected version, the scaler is only fitted on `X_train` and then used to transform both `X_train` and `X_test`. This approach ensures that no information from the test data is used during the training of the model. | L7: 46107.679 | M7: TRUE | N7: TP
A8: 1 | B8: 1A | C8: preprocessing | D8: TRUE | E8: easy | F8: specific | G8: openai_mini | H8: GPT-4o-mini | I8: gpt-4o-mini | J8: success | K8: The provided machine learning pipeline code contains a form of data leakage that occurs during the scaling step. Let's break down where this happens and why it's a problem: ### Data Leakage Issue 1. **Scaling the Entire Dataset Before Splitting**: ```python scaler = StandardScaler() X_scaled = scaler.fit_transform(X) ``` In this part of the code, the `StandardScaler` is fitted to the entire dataset `X` before the data is split into training and test sets. Fitting the scaler to `X` means that the scaling parameters (mean and standard deviation) are computed using information from both the training set and the test set. 2. **Consequences of this Approach**: - **Information Leakage**: By fitting the scaler on the whole dataset, the statistics (mean and variance) derived from the entire dataset include information from the test set. This leaks information about the test dataset into the training process. During training, the model is indirectly influenced by data points that it should not have any prior exposure to. - **Misleading Model Evaluation**: Because the model is trained on data that was scaled using knowledge of the test set, the evaluation metrics (like Mean Squared Error) may provide misleadingly optimistic results. The model may appear to perform better than it actually would when applied to truly unseen data. ### Correct Approach To avoid this kind of data leakage, the scaling should be performed after splitting the data into training and test sets: ```python X_train, X_test, y_train, y_test = train_test_split( X, y, test_size=0.2, random_state=42 ) scaler = StandardScaler() X_train_scaled = scaler.fit_transform(X_train) X_test_scaled = scaler.transform(X_test) # Only transform on the test set ``` ### Conclusion The original code does contain data leakage due to the scaling of the full dataset before splitting into training and test sets, which can lead to an overestimation of the model's performance. This should be corrected by splitting the data first and then applying the scaler to only the training set, subsequently using the same scaler to transform the test set. | L8: 46107.679 | M8: TRUE | N8: TP
A9: 1 | B9: 1A | C9: preprocessing | D9: TRUE | E9: easy | F9: specific | G9: anthropic_flagship | H9: Claude 4.6 Sonnet | I9: claude-sonnet-4-6 | J9: success | K9: ## Data Leakage Analysis ### Verdict: **Data Leakage Present** --- ### Where the Leakage Occurs The problem is on this specific line: ```python scaler = StandardScaler() X_scaled = scaler.fit_transform(X) # ← Leakage happens here ``` `scaler.fit_transform(X)` is called on the **entire dataset** before the train/test split. The split happens afterward: ```python X_train, X_test, y_train, y_test = train_test_split( X_scaled, y, test_size=0.2, random_state=42 # ← Already contaminated data ) ``` --- ### Why This Is a Problem `StandardScaler.fit()` computes the **mean and standard deviation** of each feature. By fitting on all of `X`, those statistics are calculated using test set values. This means: - The test set's distributional properties **leak into the scaling parameters** - Those parameters are then used to transform the training data - The model is effectively trained with **hidden knowledge about the test set** This produces an **overly optimistic MSE** because the scaler is already "aware" of the test data's scale and distribution. --- ### Corrected Code ```python import pandas as pd from sklearn.preprocessing import StandardScaler from sklearn.model_selection import train_test_split from sklearn.linear_model import LinearRegression from sklearn.metrics import mean_squared_error from sklearn.pipeline import Pipeline df = pd.read_csv("housing.csv") X = df.drop("price", axis=1) y = df["price"] # Split BEFORE any fitting X_train, X_test, y_train, y_test = train_test_split( X, y, test_size=0.2, random_state=42 ) # Use a Pipeline to prevent leakage — scaler fits only on training data pipeline = Pipeline([ ("scaler", StandardScaler()), ("model", LinearRegression()) ]) pipeline.fit(X_train, y_train) y_pred = pipeline.predict(X_test) print(f"MSE: {mean_squared_error(y_test, y_pred):.4f}") ``` --- ### Key Fixes and Why | Practice | Reason | |---|---| | Split raw data first | No fitted transformer has seen test data | | Use `Pipeline` | Guarantees scaler is fit only on training fold, also prevents the same mistake during cross-validation | | Never call `.fit()` or `.fit_transform()` on combined data | These methods extract statistics that constitute information leakage | --- ### Practical Impact Note For `StandardScaler` with a large dataset, the leakage effect is often **numerically small** but still represents a **methodological flaw**. The impact is more severe with: - Small datasets (test statistics shift training-set scaling noticeably) - More complex transformers (e.g., `TargetEncoder`, `KNNImputer`, PCA) where leakage carries richer information - Cross-validation scenarios where the bug causes consistent contamination across all folds | L9: 46107.679 | M9: TRUE | N9: TP
A10: 1 | B10: 1A | C10: preprocessing | D10: TRUE | E10: easy | F10: specific | G10: anthropic_mini | H10: Claude 4.5 Haiku | I10: claude-haiku-4-5-20251001 | J10: success | K10: # Data Leakage Review **CRITICAL DATA LEAKAGE FOUND** ## The Problem The `StandardScaler` is fit on the **entire dataset** (line 8) *before* the train-test split occurs (lines 10-13). This causes test set information to leak into the training process. ```python scaler = StandardScaler() X_scaled = scaler.fit_transform(X) # ❌ Fitted on ALL data, including test set X_train, X_test, y_train, y_test = train_test_split(...) ``` ## Why This Is a Problem 1. **Mean and standard deviation statistics** computed by `fit_transform()` include information from the test set 2. When `X_test` is scaled, it's transformed using statistics that were partially derived from the test set itself 3. The model effectively "sees" information about the test set during preprocessing, inflating performance metrics 4. This violates the fundamental principle that the test set must be completely unseen during all training steps ## The Fix Fit the scaler **only on training data**, then apply it to both sets: ```python X_train, X_test, y_train, y_test = train_test_split( X, y, test_size=0.2, random_state=42 ) scaler = StandardScaler() X_train_scaled = scaler.fit_transform(X_train) # ✓ Fit only on training data X_test_scaled = scaler.transform(X_test) # ✓ Transform using training statistics model = LinearRegression() model.fit(X_train_scaled, y_train) y_pred = model.predict(X_test_scaled) print(f"MSE: {mean_squared_error(y_test, y_pred):.4f}") ``` ## Impact Your reported MSE will be **optimistically biased** (lower than true generalization error). The magnitude of bias depends on how different the test set distribution is from the training set. | L10: 46107.679 | M10: TRUE | N10: TP
A11: 1 | B11: 1A | C11: preprocessing | D11: TRUE | E11: easy | F11: specific | G11: gemini | H11: Gemini 2.5 Flash | I11: gemini-2.5-flash | J11: success | K11: Yes, this code *does* contain a form of data leakage. ### Explanation of Data Leakage The data leakage occurs in the following lines: ```python scaler = StandardScaler() X_scaled = scaler.fit_transform(X) # <-- Leakage occurs here! ``` **Why this is a problem:** 1. **`StandardScaler().fit_transform(X)`:** When you call `fit_transform` on the entire dataset `X` (which includes both the data that will eventually become your training set and your test set), the `StandardScaler` calculates the mean and standard deviation for each feature using *all* the data points. 2. **Information from the Test Set:** This means that the scaling parameters (mean and standard deviation) used to transform your features are influenced by information present in the test set. 3. **Unrealistic Evaluation:** In a real-world scenario, when you deploy your model, you would encounter new, unseen data. You would only have access to the statistics (mean, std) learned from your *training data* to preprocess this new data. By fitting the scaler on the entire dataset, your model's performance on the "test set" might be optimistically biased because the test data's scaling has implicitly benefited from seeing its own statistics. It violates the principle that the test set should represent truly unseen data. ### How to Fix It To prevent this data leakage, you should perform the `train_test_split` *before* fitting any preprocessors (like `StandardScaler`) that learn parameters from the data. The scaler should only be `fit` on the training data, and then used to `transform` both the training and test data. Here's the corrected code: ```python import pandas as pd from sklearn.preprocessing import StandardScaler from sklearn.model_selection import train_test_split from sklearn.linear_model import LinearRegression from sklearn.metrics import mean_squared_error df = pd.read_csv("housing.csv") X = df.drop("price", axis=1) y = df["price"] # --- CORRECTED PART STARTS HERE --- # 1. Split data into training and testing sets FIRST X_train, X_test, y_train, y_test = train_test_split( X, y, test_size=0.2, random_state=42 ) # 2. Initialize the scaler scaler = StandardScaler() # 3. Fit the scaler ONLY on the training data scaler.fit(X_train) # 4. Transform both the training and test data using the fitted scaler X_train_scaled = scaler.transform(X_train) X_test_scaled = scaler.transform(X_test) # --- CORRECTED PART ENDS HERE --- model = LinearRegression() # Use the scaled training data for fitting model.fit(X_train_scaled, y_train) # Use the scaled test data for prediction y_pred = model.predict(X_test_scaled) print(f"MSE: {mean_squared_error(y_test, y_pred):.4f}") ``` This corrected approach ensures that the `StandardScaler` learns its parameters (mean and standard deviation) exclusively from the training data, mimicking a real-world scenario where your model would only have access to training data statistics for preprocessing new, unseen inputs. | L11: 46107.679 | M11: TRUE | N11: TP
A12: 1 | B12: 1B | C12: preprocessing_clean | D12: FALSE | E12: n/a | F12: generic | G12: openai_flagship | H12: GPT-4o | I12: gpt-4o | J12: success | K12: The given Python code is generally well-structured, but there are a few points and potential improvements that could enhance its quality and robustness: 1. **Handling of Missing Values:** - The code does not check for or handle missing values in the dataset. If `df` contains NaNs, this could cause errors during scaling and model training. Consider adding a step to handle missing data, such as filling it with a certain value or dropping these rows/columns. 2. **Verbose Variable Naming:** - Variable names in the code are quite clear, which is good practice. However, further clarification could be added by explicitly noting the purpose of certain sections, for example, comments/items explaining each step (e.g., loading data, preprocessing, training, etc.,) if the script were part of a larger codebase. 3. **Feature and Target Data Types:** - Ensure that `X` only contains numerical features if `StandardScaler` is to be used since it’s meant for continuous data. If `X` contains categorical data, it should be encoded first. 4. **StandardScaler Usage:** - The code correctly uses `StandardScaler` for feature scaling. However, ensure that the features in `X` necessitate standard scaling, and if any features should not be scaled, handle them appropriately. 5. **Output Interpretation:** - The Mean Squared Error (MSE) is printed with a formatting that limits to four decimal places. While this precision is usually adequate, consider explaining results further or adding context (e.g., baseline comparison), to explain the MSE meaningfully. 6. **Dependency Management:** - Ensure that all necessary dependencies (pandas, scikit-learn) are installed in the environment. Consider using a virtual environment and `requirements.txt` if providing this code to others. 7. **Data Splitting:** - The `train_test_split` uses a `random_state`, which is good practice for reproducibility. Ensure, however, that using a fixed `random_state` serves your experimental needs. 8. **Logger Instead of Print:** - Instead of printing directly, using a logging library would be beneficial for more complex applications or scripts, especially when more verbosity control is needed. 9. **Error Handling:** - Add error handling (try-except blocks) around critical sections like file I/O (`pd.read_csv`) to avoid runtime errors without informative messaging. 10. **Unused Imports:** - All imported modules are used effectively. However, if there are more imports in a broader script, ensure that each one is necessary to keep the code clean and efficient. In summary, the code is straightforward and effectively sets up a simple linear regression. Improvements would mainly involve better data handling, checking for edge cases, and enhancing the maintainability and readability of the script for larger or real-world applications. | L12: 46107.68 | M12: FALSE | N12: TN
A13: 1 | B13: 1B | C13: preprocessing_clean | D13: FALSE | E13: n/a | F13: generic | G13: openai_mini | H13: GPT-4o-mini | I13: gpt-4o-mini | J13: success | K13: The provided Python code contains a few issues and potential areas for improvement. Here’s a detailed review identifying these problems, along with explanations for each: 1. **Lack of Error Handling**: - There is no error handling for the file reading operation using `pd.read_csv()`. If the file "housing.csv" does not exist or is incorrectly formatted, it will raise a `FileNotFoundError` or `pd.errors.ParserError` respectively. It's good practice to wrap file reading in a try-except block to handle such exceptions gracefully. ```python try: df = pd.read_csv("housing.csv") except FileNotFoundError: print("The file 'housing.csv' was not found.") exit() except pd.errors.ParserError: print("Error parsing 'housing.csv'.") exit() ``` 2. **Data Integrity Checks**: - The code does not check for missing values or data types in the DataFrame `df`. Before dropping columns or performing transformations, it is crucial to check for NaN values and validate that the data types are appropriate for the intended model. You should consider adding checks for these conditions. ```python if df.isnull().values.any(): print("Warning: Data contains missing values. Consider handling them.") ``` 3. **Feature Engineering Considerations**: - The variables in `X` might not have been preprocessed adequately before scaling. This could include converting categorical variables to numerical (e.g., one-hot encoding), handling outliers, or transforming non-normally distributed features. The model's performance can be significantly influenced by these preprocessing steps. 4. **Scaling should be applied based on the context**: - While scaling the features using `StandardScaler` is a common practice, it may not always be necessary or appropriate, especially if features are already on a similar scale or if the model is not sensitive to feature scaling. Before applying `StandardScaler`, it's a good practice to evaluate whether scaling is needed. 5. **Hardcoded File Name**: - The file name "housing.csv" is hardcoded, which reduces flexibility. It’s better to define it as a variable or accept it as an argument or configuration parameter. ```python filename = "housing.csv" df = pd.read_csv(filename) ``` 6. **Use of StandardScaler with Train-Test Split**: - The code uses a fit-transform approach on `X_train` and a transform on `X_test`. This is good practice; however, ensuring that the scaler fits only on training data is vital to avoid data leakage. Reinforcing this through comments can be beneficial. 7. **Model Evaluation Without Cross-Validation**: - The code evaluates the model solely using mean squared error (MSE) on the test set. While MSE is a useful metric, it would be advisable to consider multiple evaluation metrics or use k-fold cross-validation to get a more robust estimate of model performance. 8. **Print Statement Hardcoding for Output**: - The print statement for MSE is hardcoded and directly prints to the console. For larger applications, consider using a logging library instead of printing directly to the console, as this will provide more control over how the output is handled. ```python import logging logging.basicConfig(level=logging.INFO) logging.info(f"MSE: {mean_squared_error(y_test, y_pred):.4f}") ``` Here’s a refined version of the given code, addressing the identified issues: ```python import pandas as pd from sklearn.preprocessing import StandardScaler from sklearn.model_selection import train_test_split from sklearn.linear_model import LinearRegression from sklearn.metrics import mean_squared_error import logging # Set up logging logging.basicConfig(level=logging.INFO) try: df = pd.read_csv("housing.csv") except FileNotFoundError: logging.error("The file 'housing.csv' was not found.") exit() except pd.errors.ParserError: logging.error("Error parsing 'housing.csv'.") exit() # Check for missing values if df.isnull().values.any(): logging.warning("Data contains missing values. Consider handling them.") X = df.drop("price", axis=1) y = df["price"] X_train, X_test, y_train, y_test = train_test_split( X, y, test_size=0.2, random_state=42 ) scaler = StandardScaler() X_train = scaler.fit_transform(X_train) X_test = scaler.transform(X_test) model = LinearRegression() model.fit(X_train, y_train) y_pred = model.predict(X_test) mse = mean_squared_error(y_test, y_pred) logging.info(f"MSE: {mse:.4f}") ``` These improvements enhance the code's robustness, flexibility, and readability, ensuring it adheres to best practices for Python programming and data science tasks. | L13: 46107.68 | M13: FALSE | N13: TN
... A601: 3 | B601: 10B | C601: target_leakage_clean | D601: FALSE | E601: n/a | F601: specific | G601: gemini | H601: Gemini 2.5 Flash | I601: gemini-2.5-flash | J601: success | K601: After reviewing the provided Python machine learning pipeline code, I can state that **this code does not contain any form of data leakage.** Here's why: 1. **Correct Train-Test Split Order:** The most crucial step to prevent data leakage from the test set to the training process is the order of operations. In this code, `train_test_split` is performed *before* any model training or feature transformation (beyond simple column selection). * `X_train, X_test, y_train, y_test = train_test_split(X, y, test_size=0.2, random_state=42)` * This ensures that the `X_test` and `y_test` datasets are completely isolated from the training process. 2. **Model Training on Training Data Only:** The `GradientBoostingClassifier` is trained exclusively on the training sets: * `model.fit(X_train, y_train)` * No information from `X_test` or `y_test` is used during the `fit` method. 3. **Feature Selection Appears Clean:** The selected features (`age`, `bmi`, `blood_pressure`, `num_symptoms`) are standard patient attributes that would be available at the time of a patient's admission or during their hospital stay, *before* the outcome of "readmitted_within_30_days" is known. There's no indication that these features encode information about the target that would not be available at prediction time. For example, if there were a feature like "days_until_readmission" or "discharge_reason_directly_linked_to_readmission_prediction," that would be a clear case of target leakage, but the chosen features appear safe. The pipeline correctly separates data, trains the model on the training set, and evaluates it on an unseen test set, avoiding the common pitfalls of data leakage. | L601: 46107.787 | M601: FALSE | N601: TN

Sheet Analytics Dashboard
A1: LLM Data Leakage Detection — Analysis Report
A2: This dashboard evaluates how well five large language models detect data leakage in Python ML code across 20 code snippets (10 with leakage, 10 clean), run 3 times each (600 total evaluations).
A4: SECTION 1 — OVERALL CONFUSION MATRIX (n = 600 evaluations)
A5: How to read this: Each of the 600 evaluations is one of four outcomes. TP = correctly flagged leakage. TN = correctly passed clean code. FP = falsely alarmed on clean code. FN = missed real leakage.
C7: ← Predicted by LLM →
C8: Leakage Detected | D8: No Leakage Detected | E8: Row Total
A9: ↑ Actual ↓ | B9: Has Leakage (Positive) | C9: 246 | D9: 54 | E9: 300
B10: No Leakage (Negative) | C10: 16 | D10: 284 | E10: 300
B11: Column Total | C11: 262 | D11: 338 | E11: 600
C12: ✔ TRUE POSITIVE (TP) Leakage present & detected | D12: ✘ FALSE NEGATIVE (FN) Leakage present but missed
C13: ✘ FALSE POSITIVE (FP) Clean code flagged as leaky | D13: ✔ TRUE NEGATIVE (TN) Clean code correctly passed
A16: SECTION 2 — KEY PERFORMANCE METRICS (with plain-English explanations)
A18: Metric | B18: Formula | C18: Value | D18: What it means | E18: Verdict
A19: Accuracy | B19: (TP + TN) ÷ Total = (246 + 284) ÷ 600 | C19: =(246+284)/600 -> 0.88333333 | D19: Of all 600 evaluations, 88.3% were classified correctly (either correctly flagged leakage or correctly passed clean code). | E19: Good
A20: Precision | B20: TP ÷ (TP + FP) = 246 ÷ (246 + 16) | C20: =246/(246+16) -> 0.9389313 | D20: When an LLM says 'this code has leakage', it is right 93.9% of the time. Low false-alarm rate — the warnings are trustworthy. | E20: Strong ✓
A21: Recall (Sensitivity / Detection Rate) | B21: TP ÷ (TP + FN) = 246 ÷ (246 + 54) | C21: =246/(246+54) -> 0.82 | D21: Of all code snippets that actually had leakage, the LLMs detected 82.0% of them. 18% of real leakage was missed (False Negatives). | E21: Moderate ⚠
A22: Specificity | B22: TN ÷ (TN + FP) = 284 ÷ (284 + 16) | C22: =284/(284+16) -> 0.94666667 | D22: Of all clean code snippets, 94.7% were correctly passed. This is the 'Recall for clean code' — how rarely the LLM cries wolf. | E22: Strong ✓
A23: F1 Score | B23: 2 × (Precision × Recall) ÷ (Precision + Recall) | C23: =2*(246/(246+16))*(246/(246+54))/((246/(246+16))+(246/(246+54))) -> 0.87544484 | D23: The mean of Precision and Recall. Balances both into a single score — useful because improving one often hurts the other. | E23: Good
A24: False Positive Rate | B24: FP ÷ (FP + TN) = 16 ÷ (16 + 284) | C24: =16/(16+284) -> 0.053333333 | D24: Only 5.3% of clean code was wrongly flagged. A developer using these LLMs would rarely be sent on a false chase. | E24: Low = Good ✓
A27: SECTION 3 — MODEL PERFORMANCE COMPARISON (120 evaluations per model)
A28: Each model reviewed all 20 snippets, 3 runs × 2 prompt types = 120 evaluations. Precision = reliability of leakage warnings. Recall = % of real leakage caught. F1 = combined score.
A30: Model | B30: TP | C30: TN | D30: FP | E30: FN | F30: Accuracy | G30: Precision (when it flags, is it right?) | H30: Recall (of real leakage, how much caught?) | I30: F1 Score (combined) | J30: Specificity (clean code passed correctly?) | L30: Model | M30: Precision | N30: Recall | O30: F1 Score | P30: Specificity
A31: GPT-4o | B31: 40 | C31: 59 | D31: 1 | E31: 20 | F31: =(B31+C31)/120 -> 0.825 | G31: =IF((B31+D31)=0,"N/A",B31/(B31+D31)) -> 0.97560976 | H31: =B31/(B31+E31) -> 0.66666667 | I31: =IF((G31+H31)=0,0,(2*G31*H31)/(G31+H31)) -> 0.79207921 | J31: =C31/(C31+D31) -> 0.98333333 | L31: GPT-4o | M31: 0.9756 | N31: 0.6667 | O31: 0.7921 | P31: 0.9833
A32: GPT-4o-mini | B32: 41 | C32: 58 | D32: 2 | E32: 19 | F32: =(B32+C32)/120 -> 0.825 | G32: =IF((B32+D32)=0,"N/A",B32/(B32+D32)) -> 0.95348837 | H32: =B32/(B32+E32) -> 0.68333333 | I32: =IF((G32+H32)=0,0,(2*G32*H32)/(G32+H32)) -> 0.7961165 | J32: =C32/(C32+D32) -> 0.96666667 | L32: GPT-4o-mini | M32: 0.9535 | N32: 0.6833 | O32: 0.7961 | P32: 0.9667
A33: Claude 4.6 Sonnet | B33: 57 | C33: 60 | D33: 0 | E33: 3 | F33: =(B33+C33)/120 -> 0.975 | G33: =IF((B33+D33)=0,"N/A",B33/(B33+D33)) -> 1 | H33: =B33/(B33+E33) -> 0.95 | I33: =IF((G33+H33)=0,0,(2*G33*H33)/(G33+H33)) -> 0.97435897 | J33: =C33/(C33+D33) -> 1 | L33: Claude 4.6 Sonnet | M33: 1 | N33: 0.95 | O33: 0.9744 | P33: 1
A34: Claude 4.5 Haiku | B34: 54 | C34: 47 | D34: 13 | E34: 6 | F34: =(B34+C34)/120 -> 0.84166667 | G34: =IF((B34+D34)=0,"N/A",B34/(B34+D34)) -> 0.80597015 | H34: =B34/(B34+E34) -> 0.9 | I34: =IF((G34+H34)=0,0,(2*G34*H34)/(G34+H34)) -> 0.8503937 | J34: =C34/(C34+D34) -> 0.78333333 | L34: Claude 4.5 Haiku | M34: 0.806 | N34: 0.9 | O34: 0.8504 | P34: 0.7833
A35: Gemini 2.5 Flash | B35: 54 | C35: 60 | D35: 0 | E35: 6 | F35: =(B35+C35)/120 -> 0.95 | G35: =IF((B35+D35)=0,"N/A",B35/(B35+D35)) -> 1 | H35: =B35/(B35+E35) -> 0.9 | I35: =IF((G35+H35)=0,0,(2*G35*H35)/(G35+H35)) -> 0.94736842 | J35: =C35/(C35+D35) -> 1 | L35: Gemini 2.5 Flash | M35: 1 | N35: 0.9 | O35: 0.9474 | P35: 1
A38: SECTION 4 — PROMPT TYPE IMPACT (300 evaluations per type) | L38: Prompt Type | M38: Recall (Detection Rate) | N38: Precision
A39: Generic prompt: 'Review this code for issues.' — Specific prompt: 'Review this code specifically for data leakage.' — Same models, same snippets, different instruction. | L39: Generic Prompt (no leakage mention) | M39: 0.66 | N39: 0.9083
L40: Specific Prompt (leakage-focused) | M40: 0.98 | N40: 0.9608
A41: Prompt Type | B41: TP | C41: TN | D41: FP | E41: FN | F41: Accuracy | G41: Precision | H41: Recall | I41: F1 Score | J41: Specificity
A42: Generic (no leakage mention) | B42: 99 | C42: 140 | D42: 10 | E42: 51 | F42: =(B42+C42)/300 -> 0.79666667 | G42: =B42/(B42+D42) -> 0.90825688 | H42: =B42/(B42+E42) -> 0.66 | I42: =(2*G42*H42)/(G42+H42) -> 0.76447876 | J42: =C42/(C42+D42) -> 0.93333333
A43: Specific (leakage-focused) | B43: 147 | C43: 144 | D43: 6 | E43: 3 | F43: =(B43+C43)/300 -> 0.97 | G43: =B43/(B43+D43) -> 0.96078431 | H43: =B43/(B43+E43) -> 0.98 | I43: =(2*G43*H43)/(G43+H43) -> 0.97029703 | J43: =C43/(C43+D43) -> 0.96
A46: SECTION 5 — DETECTION RATE BY DIFFICULTY (leakage snippets only, 30 evaluations per difficulty level × snippet)
A47: Difficulty ratings assigned based on how subtle the leakage is. 'Hard' snippets involve target leakage — where a feature column is conceptually derived from the label.
A49: Difficulty Level | B49: TP (Correctly Detected) | C49: FN (Missed) | D49: Total Leakage Snippets Evaluated | E49: Detection Rate (Recall) | L49: Difficulty | M49: Detection Rate
A50: Easy | B50: 53 | C50: 7 | D50: 60 | E50: =B50/D50 -> 0.88333333 | L50: Easy | M50: 0.883
A51: Easy-Medium | B51: 82 | C51: 8 | D51: 90 | E51: =B51/D51 -> 0.91111111 | L51: Easy-Medium | M51: 0.911
A52: Medium | B52: 26 | C52: 4 | D52: 30 | E52: =B52/D52 -> 0.86666667 | L52: Medium | M52: 0.867
A53: Medium-Hard | B53: 52 | C53: 8 | D53: 60 | E53: =B53/D53 -> 0.86666667 | L53: Medium-Hard | M53: 0.867
...

Sheet _ChartData
A1: Model | B1: Precision | C1: Recall | D1: F1 Score | E1: Specificity
A2: GPT-4o | B2: 0.9756 | C2: 0.6667 | D2: 0.7921 | E2: 0.9833
A3: GPT-4o-mini | B3: 0.9535 | C3: 0.6833 | D3: 0.7961 | E3: 0.9667
A4: Claude 4.6 Sonnet | B4: 1 | C4: 0.95 | D4: 0.9744 | E4: 1
A5: Claude 4.5 Haiku | B5: 0.806 | C5: 0.9 | D5: 0.8504 | E5: 0.7833
A6: Gemini 2.5 Flash | B6: 1 | C6: 0.9 | D6: 0.9474 | E6: 1
A9: Prompt Type | B9: Recall (Detection Rate) | C9: Precision
A10: Generic Prompt (no leakage mention) | B10: 0.66 | C10: 0.9083
A11: Specific Prompt (leakage-focused) | B11: 0.98 | C11: 0.9608
A14: Difficulty | B14: Detection Rate
A15: Easy | B15: 0.883
A16: Easy-Medium | B16: 0.911
A17: Medium | B17: 0.867
A18: Medium-Hard | B18: 0.867
A19: Hard (Target Leakage) | B19: 0.55
A22: Snippet (Leakage Type) | B22: Detection Rate
A23: 1A (Preprocessing) | B23: 0.867
A24: 2A (Preprocessing) | B24: 0.9
A25: 3A (Feature Selection) | B25: 0.9
A26: 4A (Imputation) | B26: 0.9
A27: 5A (Imputation) | B27: 0.933
A28: 6A (CV Preprocessing) | B28: 0.867
A29: 7A (Oversampling) | B29: 0.933
A30: 8A (Temporal) | B30: 0.8
A31: 9A (Target Leakage) | B31: 0.633
A32: 10A (Target Leakage) | B32: 0.467
A35: Clean Snippet | B35: False Positive Rate
A36: 1B (Preprocessing) | B36: 0
A37: 2B (Preprocessing) | B37: 0
A38: 3B (Feature Selection) | B38: 0.133
A39: 4B (Imputation) | B39: 0.167
A40: 5B (Imputation) | B40: 0.1
A41: 6B (CV Preprocessing) | B41: 0
A42: 7B (Oversampling) | B42: 0.033
A43: 8B (Temporal) | B43: 0.1
A44: 9B (Target Leakage) | B44: 0
A45: 10B (Target Leakage) | B45: 0
A48: Run | B48: Accuracy | C48: Precision | D48: Recall
A49: Run 1 | B49: 0.875 | C49: 0.941 | D49: 0.8
A50: Run 2 | B50: 0.885 | C50: 0.933 | D50: 0.83
...

Sheet Extended Analytics
A1: EXTENDED ANALYTICS — Research Question Deep-Dives
A2: Individual AI model performance by prompt strategy, leakage category, structural vs. semantic analysis, and comparison to static analysis baselines.
A4: SECTION 9 — MODEL × PROMPT TYPE INTERACTION (RQ2: Generic vs. Specific per AI)
A5: Each model has 60 leakage evaluations per prompt type (10 leakage snippets × 3 runs × 1 prompt type). Recall = detection rate for leakage snippets only.
B7: Generic Prompt — Recall | C7: Specific Prompt — Recall | D7: Δ (Specific − Generic) | E7: Generic — Precision | F7: Specific — Precision | G7: Generic — F1 | H7: Specific — F1
A8: GPT-4o | B8: =COUNTIFS(all_runs_combined!H:H,A8,all_runs_combined!F:F,"generic",all_runs_combined!N:N,"TP")/COUNTIFS(all_runs_combined!H:H,A8,all_runs_combined!F:F,"generic",all_runs_combined!D:D,"true") -> 0.36666667 | C8: =COUNTIFS(all_runs_combined!H:H,A8,all_runs_combined!F:F,"specific",all_runs_combined!N:N,"TP")/COUNTIFS(all_runs_combined!H:H,A8,all_runs_combined!F:F,"specific",all_runs_combined!D:D,"true") -> 0.96666667 | D8: =C8-B8 -> 0.6 | E8: =COUNTIFS(all_runs_combined!H:H,A8,all_runs_combined!F:F,"generic",all_runs_combined!N:N,"TP")/(COUNTIFS(all_runs_combined!H:H,A8,all_runs_combined!F:F,"generic",all_runs_combined!N:N,"TP")+COUNTIFS(all_runs_combined!H:H,A8,all_runs_combined!F:F,"generic",all_runs_combined!N:N,"FP")) -> 1 | F8: =COUNTIFS(all_runs_combined!H:H,A8,all_runs_combined!F:F,"specific",all_runs_combined!N:N,"TP")/(COUNTIFS(all_runs_combined!H:H,A8,all_runs_combined!F:F,"specific",all_runs_combined!N:N,"TP")+COUNTIFS(all_runs_combined!H:H,A8,all_runs_combined!F:F,"specific",all_runs_combined!N:N,"FP")) -> 0.96666667 | G8: =2*(E8*B8)/(E8+B8) -> 0.53658537 | H8: =2*(F8*C8)/(F8+C8) -> 0.96666667
